2025-06-12 00:17:16,725 - INFO - server listening on [::1]:5001
2025-06-12 00:17:16,725 - INFO - server listening on 127.0.0.1:5001
2025-06-12 00:17:16,725 - INFO - WebSocket 서버가 시작되었습니다. ws://localhost:5001
2025-06-12 00:18:01,834 - INFO - connection open
2025-06-12 00:18:01,834 - INFO - 새로운 클라이언트 연결됨. 현재 연결 수: 1
2025-06-12 00:18:03,821 - INFO - 주문 수신: {'order_id': '23', 'customer_name': '미래새한감정평가법인', 'items': [{'name': '수비드 비프 포케', 'quantity': 1, 'price': 13900, 'options': ['100g', '소스 안먹어요 X']}], 'payment_method': '현장결제'}
2025-06-12 00:18:13,939 - INFO - 주문 수신: {'order_id': '23', 'customer_name': '미래새한감정평가법인', 'items': [{'name': '수비드 비프 포케', 'quantity': 1, 'price': 13900, 'options': ['100g', '소스 안먹어요 X']}], 'payment_method': '현장결제'}
2025-06-12 00:18:42,224 - INFO - 주문 수신: {'order_id': '23', 'customer_name': '미래새한감정평가법인', 'items': [{'name': '수비드 비프 포케', 'quantity': 1, 'price': 13900, 'options': ['100g', '소스 안먹어요 X']}], 'payment_method': '현장결제'}
2025-06-12 00:18:51,243 - INFO - 주문 수신: {'order_id': '23', 'customer_name': '미래새한감정평가법인', 'items': [{'name': '수비드 비프 포케', 'quantity': 1, 'price': 13900, 'options': ['100g', '소스 안먹어요 X']}], 'payment_method': '현장결제'}
2025-06-12 00:18:53,284 - INFO - 클라이언트 연결 해제. 현재 연결 수: 0
2025-06-12 00:18:53,577 - INFO - connection open
2025-06-12 00:18:53,578 - INFO - 새로운 클라이언트 연결됨. 현재 연결 수: 1
2025-06-12 00:18:55,209 - INFO - 주문 수신: {'order_id': '23', 'customer_name': '미래새한감정평가법인', 'items': [{'name': '수비드 비프 포케', 'quantity': 1, 'price': 13900, 'options': ['100g', '소스 안먹어요 X']}], 'payment_method': '현장결제'}
2025-06-12 00:18:57,732 - INFO - 클라이언트 연결 해제. 현재 연결 수: 0
2025-06-12 00:19:38,685 - INFO - connection open
2025-06-12 00:19:38,685 - INFO - 새로운 클라이언트 연결됨. 현재 연결 수: 1
2025-06-12 00:19:39,656 - INFO - 주문 수신: {'order_id': '24', 'customer_name': '미래새한감정평가법인', 'items': [{'name': '아토키토 포케', 'quantity': 1, 'price': 10900, 'options': ['소스 안먹어요 X']}], 'payment_method': '현장결제'}
2025-06-12 00:20:10,355 - INFO - 주문 수신: {'order_id': '24', 'customer_name': '미래새한감정평가법인', 'items': [{'name': '아토키토 포케', 'quantity': 1, 'price': 10900, 'options': ['소스 안먹어요 X']}], 'payment_method': '현장결제'}
2025-06-12 00:20:28,751 - INFO - 클라이언트 연결 해제. 현재 연결 수: 0
2025-06-12 00:23:13,765 - INFO - server listening on 127.0.0.1:5001
2025-06-12 00:23:13,765 - INFO - server listening on [::1]:5001
2025-06-12 00:23:13,765 - INFO - WebSocket 서버가 시작되었습니다. ws://localhost:5001
2025-06-12 00:24:22,175 - INFO - connection open
2025-06-12 00:24:22,176 - INFO - 새로운 클라이언트 연결됨. 현재 연결 수: 1
2025-06-12 00:24:25,627 - INFO - 주문 수신: {'order_id': '25', 'customer_name': '가온감정평가법인', 'items': [{'name': '아토키토 포케', 'quantity': 1, 'price': 10900, 'options': ['소스 안먹어요 X']}], 'payment_method': '현장결제'}
2025-06-12 00:24:26,858 - INFO - 주문 수신: {'order_id': '25', 'customer_name': '가온감정평가법인', 'items': [{'name': '아토키토 포케', 'quantity': 1, 'price': 10900, 'options': ['소스 안먹어요 X']}], 'payment_method': '현장결제'}
2025-06-12 00:34:03,086 - INFO - connection open
2025-06-12 00:34:03,086 - INFO - 새로운 클라이언트 연결됨. 현재 연결 수: 2
2025-06-12 00:34:11,723 - INFO - 주문 수신: {'order_id': '25', 'customer_name': '가온감정평가법인', 'items': [{'name': '아토키토 포케', 'quantity': 1, 'price': 10900, 'options': ['소스 안먹어요 X']}], 'payment_method': '현장결제'}
2025-06-12 00:34:18,927 - INFO - 주문 수신: {'order_id': '25', 'customer_name': '가온감정평가법인', 'items': [{'name': '아토키토 포케', 'quantity': 1, 'price': 10900, 'options': ['소스 안먹어요 X']}], 'payment_method': '현장결제'}
2025-06-12 00:36:12,996 - INFO - connection open
2025-06-12 00:36:12,997 - INFO - 새로운 클라이언트 연결됨. 현재 연결 수: 3
2025-06-12 00:36:19,927 - INFO - 주문 수신: {'order_id': '26', 'customer_name': '가온감정평가법인', 'items': [{'name': '아토키토 포케', 'quantity': 1, 'price': 10900, 'options': ['소스 안먹어요 X']}], 'payment_method': '현장결제'}
2025-06-12 00:36:36,027 - INFO - 주문 수신: {'order_id': '26', 'customer_name': '가온감정평가법인', 'items': [{'name': '아토키토 포케', 'quantity': 1, 'price': 10900, 'options': ['소스 안먹어요 X']}], 'payment_method': '현장결제'}
2025-06-12 00:36:37,028 - INFO - 주문 수신: {'order_id': '26', 'customer_name': '가온감정평가법인', 'items': [{'name': '아토키토 포케', 'quantity': 1, 'price': 10900, 'options': ['소스 안먹어요 X']}], 'payment_method': '현장결제'}
2025-06-12 00:36:37,845 - INFO - 주문 수신: {'order_id': '26', 'customer_name': '가온감정평가법인', 'items': [{'name': '아토키토 포케', 'quantity': 1, 'price': 10900, 'options': ['소스 안먹어요 X']}], 'payment_method': '현장결제'}
2025-06-12 00:36:38,972 - INFO - 주문 수신: {'order_id': '26', 'customer_name': '가온감정평가법인', 'items': [{'name': '아토키토 포케', 'quantity': 1, 'price': 10900, 'options': ['소스 안먹어요 X']}], 'payment_method': '현장결제'}
2025-06-12 00:36:39,694 - INFO - 주문 수신: {'order_id': '26', 'customer_name': '가온감정평가법인', 'items': [{'name': '아토키토 포케', 'quantity': 1, 'price': 10900, 'options': ['소스 안먹어요 X']}], 'payment_method': '현장결제'}
2025-06-12 00:36:40,712 - INFO - 주문 수신: {'order_id': '26', 'customer_name': '가온감정평가법인', 'items': [{'name': '아토키토 포케', 'quantity': 1, 'price': 10900, 'options': ['소스 안먹어요 X']}], 'payment_method': '현장결제'}
2025-06-12 00:37:35,803 - INFO - 클라이언트 연결 해제. 현재 연결 수: 2
2025-06-12 00:37:35,805 - ERROR - connection handler failed
Traceback (most recent call last):
  File "C:\Users\Joey\OneDrive\Desktop\아토키토\printer_server\venv\Lib\site-packages\websockets\asyncio\server.py", line 376, in conn_handler
    await self.handler(connection)
  File "C:\Users\Joey\OneDrive\Desktop\아토키토\printer_server\src\websocket\server.py", line 63, in handler
    async for message in websocket:
    ...<9 lines>...
            logging.error(f"메시지 처리 중 오류 발생: {e}")
  File "C:\Users\Joey\OneDrive\Desktop\아토키토\printer_server\venv\Lib\site-packages\websockets\asyncio\connection.py", line 242, in __aiter__
    yield await self.recv()
          ^^^^^^^^^^^^^^^^^
  File "C:\Users\Joey\OneDrive\Desktop\아토키토\printer_server\venv\Lib\site-packages\websockets\asyncio\connection.py", line 322, in recv
    raise self.protocol.close_exc from self.recv_exc
websockets.exceptions.ConnectionClosedError: no close frame received or sent
2025-06-12 00:37:36,231 - INFO - 클라이언트 연결 해제. 현재 연결 수: 1
2025-06-12 10:14:37,354 - INFO - server listening on [::1]:5001
2025-06-12 10:14:37,354 - INFO - server listening on 127.0.0.1:5001
2025-06-12 10:14:37,355 - INFO - WebSocket 서버가 시작되었습니다. ws://localhost:5001
2025-06-12 10:15:39,087 - INFO - connection open
2025-06-12 10:15:39,088 - INFO - 새로운 클라이언트 연결됨. 현재 연결 수: 1
2025-06-12 10:15:48,765 - INFO - 클라이언트 연결 해제. 현재 연결 수: 0
2025-06-12 10:15:48,766 - ERROR - connection handler failed
Traceback (most recent call last):
  File "C:\Program Files\WindowsApps\PythonSoftwareFoundation.Python.3.11_3.11.2544.0_x64__qbz5n2kfra8p0\Lib\asyncio\windows_events.py", line 494, in finish_recv
    return ov.getresult()
           ^^^^^^^^^^^^^^
OSError: [WinError 64] 지정된 네트워크 이름을 더 이상 사용할 수 없습니다

During handling of the above exception, another exception occurred:

Traceback (most recent call last):
  File "C:\Program Files\WindowsApps\PythonSoftwareFoundation.Python.3.11_3.11.2544.0_x64__qbz5n2kfra8p0\Lib\asyncio\proactor_events.py", line 286, in _loop_reading
    length = fut.result()
             ^^^^^^^^^^^^
  File "C:\Program Files\WindowsApps\PythonSoftwareFoundation.Python.3.11_3.11.2544.0_x64__qbz5n2kfra8p0\Lib\asyncio\windows_events.py", line 854, in _poll
    value = callback(transferred, key, ov)
            ^^^^^^^^^^^^^^^^^^^^^^^^^^^^^^
  File "C:\Program Files\WindowsApps\PythonSoftwareFoundation.Python.3.11_3.11.2544.0_x64__qbz5n2kfra8p0\Lib\asyncio\windows_events.py", line 498, in finish_recv
    raise ConnectionResetError(*exc.args)
ConnectionResetError: [WinError 64] 지정된 네트워크 이름을 더 이상 사용할 수 없습니다

The above exception was the direct cause of the following exception:

Traceback (most recent call last):
  File "C:\Users\dohwa\AppData\Local\Packages\PythonSoftwareFoundation.Python.3.11_qbz5n2kfra8p0\LocalCache\local-packages\Python311\site-packages\websockets\asyncio\server.py", line 376, in conn_handler
    await self.handler(connection)
  File "C:\Users\dohwa\Desktop\MyPlugin\printer_server_websocket\src\websocket\server.py", line 63, in handler
    async for message in websocket:
  File "C:\Users\dohwa\AppData\Local\Packages\PythonSoftwareFoundation.Python.3.11_qbz5n2kfra8p0\LocalCache\local-packages\Python311\site-packages\websockets\asyncio\connection.py", line 242, in __aiter__
    yield await self.recv()
          ^^^^^^^^^^^^^^^^^
  File "C:\Users\dohwa\AppData\Local\Packages\PythonSoftwareFoundation.Python.3.11_qbz5n2kfra8p0\LocalCache\local-packages\Python311\site-packages\websockets\asyncio\connection.py", line 322, in recv
    raise self.protocol.close_exc from self.recv_exc
websockets.exceptions.ConnectionClosedError: no close frame received or sent
2025-06-12 10:40:14,383 - INFO - connection open
2025-06-12 10:40:14,384 - INFO - 새로운 클라이언트 연결됨. 현재 연결 수: 1
2025-06-12 10:40:19,876 - INFO - 클라이언트 연결 해제. 현재 연결 수: 0
2025-06-12 10:40:19,877 - ERROR - connection handler failed
Traceback (most recent call last):
  File "C:\Program Files\WindowsApps\PythonSoftwareFoundation.Python.3.11_3.11.2544.0_x64__qbz5n2kfra8p0\Lib\asyncio\windows_events.py", line 494, in finish_recv
    return ov.getresult()
           ^^^^^^^^^^^^^^
OSError: [WinError 64] 지정된 네트워크 이름을 더 이상 사용할 수 없습니다

During handling of the above exception, another exception occurred:

Traceback (most recent call last):
  File "C:\Program Files\WindowsApps\PythonSoftwareFoundation.Python.3.11_3.11.2544.0_x64__qbz5n2kfra8p0\Lib\asyncio\proactor_events.py", line 286, in _loop_reading
    length = fut.result()
             ^^^^^^^^^^^^
  File "C:\Program Files\WindowsApps\PythonSoftwareFoundation.Python.3.11_3.11.2544.0_x64__qbz5n2kfra8p0\Lib\asyncio\windows_events.py", line 854, in _poll
    value = callback(transferred, key, ov)
            ^^^^^^^^^^^^^^^^^^^^^^^^^^^^^^
  File "C:\Program Files\WindowsApps\PythonSoftwareFoundation.Python.3.11_3.11.2544.0_x64__qbz5n2kfra8p0\Lib\asyncio\windows_events.py", line 498, in finish_recv
    raise ConnectionResetError(*exc.args)
ConnectionResetError: [WinError 64] 지정된 네트워크 이름을 더 이상 사용할 수 없습니다

The above exception was the direct cause of the following exception:

Traceback (most recent call last):
  File "C:\Users\dohwa\AppData\Local\Packages\PythonSoftwareFoundation.Python.3.11_qbz5n2kfra8p0\LocalCache\local-packages\Python311\site-packages\websockets\asyncio\server.py", line 376, in conn_handler
    await self.handler(connection)
  File "C:\Users\dohwa\Desktop\MyPlugin\printer_server_websocket\src\websocket\server.py", line 63, in handler
    async for message in websocket:
  File "C:\Users\dohwa\AppData\Local\Packages\PythonSoftwareFoundation.Python.3.11_qbz5n2kfra8p0\LocalCache\local-packages\Python311\site-packages\websockets\asyncio\connection.py", line 242, in __aiter__
    yield await self.recv()
          ^^^^^^^^^^^^^^^^^
  File "C:\Users\dohwa\AppData\Local\Packages\PythonSoftwareFoundation.Python.3.11_qbz5n2kfra8p0\LocalCache\local-packages\Python311\site-packages\websockets\asyncio\connection.py", line 322, in recv
    raise self.protocol.close_exc from self.recv_exc
websockets.exceptions.ConnectionClosedError: no close frame received or sent
2025-06-12 10:43:52,174 - INFO - connection open
2025-06-12 10:43:52,175 - INFO - 새로운 클라이언트 연결됨. 현재 연결 수: 1
2025-06-12 10:44:20,258 - INFO - 클라이언트 연결 해제. 현재 연결 수: 0
2025-06-12 10:44:20,259 - ERROR - connection handler failed
Traceback (most recent call last):
  File "C:\Program Files\WindowsApps\PythonSoftwareFoundation.Python.3.11_3.11.2544.0_x64__qbz5n2kfra8p0\Lib\asyncio\windows_events.py", line 494, in finish_recv
    return ov.getresult()
           ^^^^^^^^^^^^^^
OSError: [WinError 64] 지정된 네트워크 이름을 더 이상 사용할 수 없습니다

During handling of the above exception, another exception occurred:

Traceback (most recent call last):
  File "C:\Program Files\WindowsApps\PythonSoftwareFoundation.Python.3.11_3.11.2544.0_x64__qbz5n2kfra8p0\Lib\asyncio\proactor_events.py", line 286, in _loop_reading
    length = fut.result()
             ^^^^^^^^^^^^
  File "C:\Program Files\WindowsApps\PythonSoftwareFoundation.Python.3.11_3.11.2544.0_x64__qbz5n2kfra8p0\Lib\asyncio\windows_events.py", line 854, in _poll
    value = callback(transferred, key, ov)
            ^^^^^^^^^^^^^^^^^^^^^^^^^^^^^^
  File "C:\Program Files\WindowsApps\PythonSoftwareFoundation.Python.3.11_3.11.2544.0_x64__qbz5n2kfra8p0\Lib\asyncio\windows_events.py", line 498, in finish_recv
    raise ConnectionResetError(*exc.args)
ConnectionResetError: [WinError 64] 지정된 네트워크 이름을 더 이상 사용할 수 없습니다

The above exception was the direct cause of the following exception:

Traceback (most recent call last):
  File "C:\Users\dohwa\AppData\Local\Packages\PythonSoftwareFoundation.Python.3.11_qbz5n2kfra8p0\LocalCache\local-packages\Python311\site-packages\websockets\asyncio\server.py", line 376, in conn_handler
    await self.handler(connection)
  File "C:\Users\dohwa\Desktop\MyPlugin\printer_server_websocket\src\websocket\server.py", line 63, in handler
    async for message in websocket:
  File "C:\Users\dohwa\AppData\Local\Packages\PythonSoftwareFoundation.Python.3.11_qbz5n2kfra8p0\LocalCache\local-packages\Python311\site-packages\websockets\asyncio\connection.py", line 242, in __aiter__
    yield await self.recv()
          ^^^^^^^^^^^^^^^^^
  File "C:\Users\dohwa\AppData\Local\Packages\PythonSoftwareFoundation.Python.3.11_qbz5n2kfra8p0\LocalCache\local-packages\Python311\site-packages\websockets\asyncio\connection.py", line 322, in recv
    raise self.protocol.close_exc from self.recv_exc
websockets.exceptions.ConnectionClosedError: no close frame received or sent
2025-06-12 14:49:03,050 - INFO - connection open
2025-06-12 14:49:03,053 - INFO - 새로운 클라이언트 연결됨. 현재 연결 수: 1
2025-06-12 16:16:21,354 - INFO - 클라이언트 연결 해제. 현재 연결 수: 0
2025-06-12 16:16:21,354 - ERROR - connection handler failed
Traceback (most recent call last):
  File "C:\Program Files\WindowsApps\PythonSoftwareFoundation.Python.3.11_3.11.2544.0_x64__qbz5n2kfra8p0\Lib\asyncio\windows_events.py", line 494, in finish_recv
    return ov.getresult()
           ^^^^^^^^^^^^^^
OSError: [WinError 64] 지정된 네트워크 이름을 더 이상 사용할 수 없습니다

During handling of the above exception, another exception occurred:

Traceback (most recent call last):
  File "C:\Program Files\WindowsApps\PythonSoftwareFoundation.Python.3.11_3.11.2544.0_x64__qbz5n2kfra8p0\Lib\asyncio\proactor_events.py", line 286, in _loop_reading
    length = fut.result()
             ^^^^^^^^^^^^
  File "C:\Program Files\WindowsApps\PythonSoftwareFoundation.Python.3.11_3.11.2544.0_x64__qbz5n2kfra8p0\Lib\asyncio\windows_events.py", line 854, in _poll
    value = callback(transferred, key, ov)
            ^^^^^^^^^^^^^^^^^^^^^^^^^^^^^^
  File "C:\Program Files\WindowsApps\PythonSoftwareFoundation.Python.3.11_3.11.2544.0_x64__qbz5n2kfra8p0\Lib\asyncio\windows_events.py", line 498, in finish_recv
    raise ConnectionResetError(*exc.args)
ConnectionResetError: [WinError 64] 지정된 네트워크 이름을 더 이상 사용할 수 없습니다

The above exception was the direct cause of the following exception:

Traceback (most recent call last):
  File "C:\Users\dohwa\AppData\Local\Packages\PythonSoftwareFoundation.Python.3.11_qbz5n2kfra8p0\LocalCache\local-packages\Python311\site-packages\websockets\asyncio\server.py", line 376, in conn_handler
    await self.handler(connection)
  File "C:\Users\dohwa\Desktop\MyPlugin\printer_server_websocket\src\websocket\server.py", line 63, in handler
    async for message in websocket:
  File "C:\Users\dohwa\AppData\Local\Packages\PythonSoftwareFoundation.Python.3.11_qbz5n2kfra8p0\LocalCache\local-packages\Python311\site-packages\websockets\asyncio\connection.py", line 242, in __aiter__
    yield await self.recv()
          ^^^^^^^^^^^^^^^^^
  File "C:\Users\dohwa\AppData\Local\Packages\PythonSoftwareFoundation.Python.3.11_qbz5n2kfra8p0\LocalCache\local-packages\Python311\site-packages\websockets\asyncio\connection.py", line 322, in recv
    raise self.protocol.close_exc from self.recv_exc
websockets.exceptions.ConnectionClosedError: no close frame received or sent
2025-06-12 16:33:54,384 - INFO - connection open
2025-06-12 16:33:54,385 - INFO - 새로운 클라이언트 연결됨. 현재 연결 수: 1
2025-06-12 16:34:16,566 - INFO - 클라이언트 연결 해제. 현재 연결 수: 0
2025-06-12 16:34:16,566 - ERROR - connection handler failed
Traceback (most recent call last):
  File "C:\Program Files\WindowsApps\PythonSoftwareFoundation.Python.3.11_3.11.2544.0_x64__qbz5n2kfra8p0\Lib\asyncio\windows_events.py", line 494, in finish_recv
    return ov.getresult()
           ^^^^^^^^^^^^^^
OSError: [WinError 64] 지정된 네트워크 이름을 더 이상 사용할 수 없습니다

During handling of the above exception, another exception occurred:

Traceback (most recent call last):
  File "C:\Program Files\WindowsApps\PythonSoftwareFoundation.Python.3.11_3.11.2544.0_x64__qbz5n2kfra8p0\Lib\asyncio\proactor_events.py", line 286, in _loop_reading
    length = fut.result()
             ^^^^^^^^^^^^
  File "C:\Program Files\WindowsApps\PythonSoftwareFoundation.Python.3.11_3.11.2544.0_x64__qbz5n2kfra8p0\Lib\asyncio\windows_events.py", line 854, in _poll
    value = callback(transferred, key, ov)
            ^^^^^^^^^^^^^^^^^^^^^^^^^^^^^^
  File "C:\Program Files\WindowsApps\PythonSoftwareFoundation.Python.3.11_3.11.2544.0_x64__qbz5n2kfra8p0\Lib\asyncio\windows_events.py", line 498, in finish_recv
    raise ConnectionResetError(*exc.args)
ConnectionResetError: [WinError 64] 지정된 네트워크 이름을 더 이상 사용할 수 없습니다

The above exception was the direct cause of the following exception:

Traceback (most recent call last):
  File "C:\Users\dohwa\AppData\Local\Packages\PythonSoftwareFoundation.Python.3.11_qbz5n2kfra8p0\LocalCache\local-packages\Python311\site-packages\websockets\asyncio\server.py", line 376, in conn_handler
    await self.handler(connection)
  File "C:\Users\dohwa\Desktop\MyPlugin\printer_server_websocket\src\websocket\server.py", line 63, in handler
    async for message in websocket:
  File "C:\Users\dohwa\AppData\Local\Packages\PythonSoftwareFoundation.Python.3.11_qbz5n2kfra8p0\LocalCache\local-packages\Python311\site-packages\websockets\asyncio\connection.py", line 242, in __aiter__
    yield await self.recv()
          ^^^^^^^^^^^^^^^^^
  File "C:\Users\dohwa\AppData\Local\Packages\PythonSoftwareFoundation.Python.3.11_qbz5n2kfra8p0\LocalCache\local-packages\Python311\site-packages\websockets\asyncio\connection.py", line 322, in recv
    raise self.protocol.close_exc from self.recv_exc
websockets.exceptions.ConnectionClosedError: no close frame received or sent
2025-06-12 16:34:27,569 - INFO - connection open
2025-06-12 16:34:27,569 - INFO - 새로운 클라이언트 연결됨. 현재 연결 수: 1
2025-06-12 16:39:10,695 - INFO - 클라이언트 연결 해제. 현재 연결 수: 0
2025-06-12 16:39:10,696 - ERROR - connection handler failed
Traceback (most recent call last):
  File "C:\Program Files\WindowsApps\PythonSoftwareFoundation.Python.3.11_3.11.2544.0_x64__qbz5n2kfra8p0\Lib\asyncio\windows_events.py", line 494, in finish_recv
    return ov.getresult()
           ^^^^^^^^^^^^^^
OSError: [WinError 64] 지정된 네트워크 이름을 더 이상 사용할 수 없습니다

During handling of the above exception, another exception occurred:

Traceback (most recent call last):
  File "C:\Program Files\WindowsApps\PythonSoftwareFoundation.Python.3.11_3.11.2544.0_x64__qbz5n2kfra8p0\Lib\asyncio\proactor_events.py", line 286, in _loop_reading
    length = fut.result()
             ^^^^^^^^^^^^
  File "C:\Program Files\WindowsApps\PythonSoftwareFoundation.Python.3.11_3.11.2544.0_x64__qbz5n2kfra8p0\Lib\asyncio\windows_events.py", line 854, in _poll
    value = callback(transferred, key, ov)
            ^^^^^^^^^^^^^^^^^^^^^^^^^^^^^^
  File "C:\Program Files\WindowsApps\PythonSoftwareFoundation.Python.3.11_3.11.2544.0_x64__qbz5n2kfra8p0\Lib\asyncio\windows_events.py", line 498, in finish_recv
    raise ConnectionResetError(*exc.args)
ConnectionResetError: [WinError 64] 지정된 네트워크 이름을 더 이상 사용할 수 없습니다

The above exception was the direct cause of the following exception:

Traceback (most recent call last):
  File "C:\Users\dohwa\AppData\Local\Packages\PythonSoftwareFoundation.Python.3.11_qbz5n2kfra8p0\LocalCache\local-packages\Python311\site-packages\websockets\asyncio\server.py", line 376, in conn_handler
    await self.handler(connection)
  File "C:\Users\dohwa\Desktop\MyPlugin\printer_server_websocket\src\websocket\server.py", line 63, in handler
    async for message in websocket:
  File "C:\Users\dohwa\AppData\Local\Packages\PythonSoftwareFoundation.Python.3.11_qbz5n2kfra8p0\LocalCache\local-packages\Python311\site-packages\websockets\asyncio\connection.py", line 242, in __aiter__
    yield await self.recv()
          ^^^^^^^^^^^^^^^^^
  File "C:\Users\dohwa\AppData\Local\Packages\PythonSoftwareFoundation.Python.3.11_qbz5n2kfra8p0\LocalCache\local-packages\Python311\site-packages\websockets\asyncio\connection.py", line 322, in recv
    raise self.protocol.close_exc from self.recv_exc
websockets.exceptions.ConnectionClosedError: no close frame received or sent
2025-06-12 16:39:17,688 - INFO - server closing
2025-06-12 16:39:17,689 - INFO - server closed
2025-06-12 16:39:51,811 - INFO - server listening on 127.0.0.1:5001
2025-06-12 16:39:51,811 - INFO - server listening on [::1]:5001
2025-06-12 16:39:51,811 - INFO - WebSocket 서버가 시작되었습니다. ws://localhost:5001
2025-06-12 16:40:11,468 - INFO - connection open
2025-06-12 16:40:11,468 - INFO - 새로운 클라이언트 연결됨. 현재 연결 수: 1
2025-06-12 16:40:30,910 - INFO - 클라이언트 연결 해제. 현재 연결 수: 0
2025-06-12 16:40:30,910 - ERROR - connection handler failed
Traceback (most recent call last):
  File "C:\Program Files\WindowsApps\PythonSoftwareFoundation.Python.3.11_3.11.2544.0_x64__qbz5n2kfra8p0\Lib\asyncio\windows_events.py", line 494, in finish_recv
    return ov.getresult()
           ^^^^^^^^^^^^^^
OSError: [WinError 64] 지정된 네트워크 이름을 더 이상 사용할 수 없습니다

During handling of the above exception, another exception occurred:

Traceback (most recent call last):
  File "C:\Program Files\WindowsApps\PythonSoftwareFoundation.Python.3.11_3.11.2544.0_x64__qbz5n2kfra8p0\Lib\asyncio\proactor_events.py", line 286, in _loop_reading
    length = fut.result()
             ^^^^^^^^^^^^
  File "C:\Program Files\WindowsApps\PythonSoftwareFoundation.Python.3.11_3.11.2544.0_x64__qbz5n2kfra8p0\Lib\asyncio\windows_events.py", line 854, in _poll
    value = callback(transferred, key, ov)
            ^^^^^^^^^^^^^^^^^^^^^^^^^^^^^^
  File "C:\Program Files\WindowsApps\PythonSoftwareFoundation.Python.3.11_3.11.2544.0_x64__qbz5n2kfra8p0\Lib\asyncio\windows_events.py", line 498, in finish_recv
    raise ConnectionResetError(*exc.args)
ConnectionResetError: [WinError 64] 지정된 네트워크 이름을 더 이상 사용할 수 없습니다

The above exception was the direct cause of the following exception:

Traceback (most recent call last):
  File "C:\Users\dohwa\AppData\Local\Packages\PythonSoftwareFoundation.Python.3.11_qbz5n2kfra8p0\LocalCache\local-packages\Python311\site-packages\websockets\asyncio\server.py", line 376, in conn_handler
    await self.handler(connection)
  File "C:\Users\dohwa\Desktop\MyPlugin\printer_server_websocket\src\websocket\server.py", line 63, in handler
    async for message in websocket:
  File "C:\Users\dohwa\AppData\Local\Packages\PythonSoftwareFoundation.Python.3.11_qbz5n2kfra8p0\LocalCache\local-packages\Python311\site-packages\websockets\asyncio\connection.py", line 242, in __aiter__
    yield await self.recv()
          ^^^^^^^^^^^^^^^^^
  File "C:\Users\dohwa\AppData\Local\Packages\PythonSoftwareFoundation.Python.3.11_qbz5n2kfra8p0\LocalCache\local-packages\Python311\site-packages\websockets\asyncio\connection.py", line 322, in recv
    raise self.protocol.close_exc from self.recv_exc
websockets.exceptions.ConnectionClosedError: no close frame received or sent
2025-06-12 16:41:42,268 - INFO - server listening on [::1]:5001
2025-06-12 16:41:42,268 - INFO - server listening on 127.0.0.1:5001
2025-06-12 16:41:42,269 - INFO - WebSocket 서버가 시작되었습니다. ws://localhost:5001
2025-06-12 16:48:39,127 - INFO - connection rejected (426 Upgrade Required)
2025-06-12 16:48:39,128 - ERROR - opening handshake failed
Traceback (most recent call last):
  File "C:\Users\dohwa\AppData\Local\Packages\PythonSoftwareFoundation.Python.3.11_qbz5n2kfra8p0\LocalCache\local-packages\Python311\site-packages\websockets\asyncio\server.py", line 356, in conn_handler
    await connection.handshake(
  File "C:\Users\dohwa\AppData\Local\Packages\PythonSoftwareFoundation.Python.3.11_qbz5n2kfra8p0\LocalCache\local-packages\Python311\site-packages\websockets\asyncio\server.py", line 207, in handshake
    raise self.protocol.handshake_exc
  File "C:\Users\dohwa\AppData\Local\Packages\PythonSoftwareFoundation.Python.3.11_qbz5n2kfra8p0\LocalCache\local-packages\Python311\site-packages\websockets\server.py", line 138, in accept
    ) = self.process_request(request)
        ^^^^^^^^^^^^^^^^^^^^^^^^^^^^^
  File "C:\Users\dohwa\AppData\Local\Packages\PythonSoftwareFoundation.Python.3.11_qbz5n2kfra8p0\LocalCache\local-packages\Python311\site-packages\websockets\server.py", line 233, in process_request
    raise InvalidUpgrade(
websockets.exceptions.InvalidUpgrade: missing Connection header
2025-06-12 16:48:52,577 - INFO - connection rejected (426 Upgrade Required)
2025-06-12 16:48:52,578 - ERROR - opening handshake failed
Traceback (most recent call last):
  File "C:\Users\dohwa\AppData\Local\Packages\PythonSoftwareFoundation.Python.3.11_qbz5n2kfra8p0\LocalCache\local-packages\Python311\site-packages\websockets\asyncio\server.py", line 356, in conn_handler
    await connection.handshake(
  File "C:\Users\dohwa\AppData\Local\Packages\PythonSoftwareFoundation.Python.3.11_qbz5n2kfra8p0\LocalCache\local-packages\Python311\site-packages\websockets\asyncio\server.py", line 207, in handshake
    raise self.protocol.handshake_exc
  File "C:\Users\dohwa\AppData\Local\Packages\PythonSoftwareFoundation.Python.3.11_qbz5n2kfra8p0\LocalCache\local-packages\Python311\site-packages\websockets\server.py", line 138, in accept
    ) = self.process_request(request)
        ^^^^^^^^^^^^^^^^^^^^^^^^^^^^^
  File "C:\Users\dohwa\AppData\Local\Packages\PythonSoftwareFoundation.Python.3.11_qbz5n2kfra8p0\LocalCache\local-packages\Python311\site-packages\websockets\server.py", line 233, in process_request
    raise InvalidUpgrade(
websockets.exceptions.InvalidUpgrade: missing Connection header
2025-06-12 16:49:15,984 - INFO - server closing
2025-06-12 16:49:15,985 - INFO - server closed
2025-06-12 16:50:25,263 - INFO - server listening on [::1]:5001
2025-06-12 16:50:25,264 - INFO - server listening on 127.0.0.1:5001
2025-06-12 16:50:25,264 - INFO - WebSocket 서버가 시작되었습니다. ws://localhost:5001
2025-06-12 17:16:51,402 - INFO - connection open
2025-06-12 17:16:51,402 - INFO - 새로운 클라이언트 연결됨. 현재 연결 수: 1
2025-06-12 17:17:21,810 - INFO - connection open
2025-06-12 17:17:21,810 - INFO - 새로운 클라이언트 연결됨. 현재 연결 수: 2
2025-06-12 17:17:22,381 - INFO - 주문 수신: {'order_id': '27', 'customer_name': '미래새한감정평가법인', 'items': [{'name': '아토키토 포케', 'quantity': 1, 'price': 10900, 'options': ['소스 안먹어요 X']}], 'payment_method': '현장결제'}
2025-06-12 17:17:36,868 - INFO - 클라이언트 연결 해제. 현재 연결 수: 1
2025-06-12 17:17:36,868 - ERROR - connection handler failed
Traceback (most recent call last):
  File "C:\Program Files\WindowsApps\PythonSoftwareFoundation.Python.3.11_3.11.2544.0_x64__qbz5n2kfra8p0\Lib\asyncio\windows_events.py", line 494, in finish_recv
    return ov.getresult()
           ^^^^^^^^^^^^^^
OSError: [WinError 64] 지정된 네트워크 이름을 더 이상 사용할 수 없습니다

During handling of the above exception, another exception occurred:

Traceback (most recent call last):
  File "C:\Program Files\WindowsApps\PythonSoftwareFoundation.Python.3.11_3.11.2544.0_x64__qbz5n2kfra8p0\Lib\asyncio\proactor_events.py", line 286, in _loop_reading
    length = fut.result()
             ^^^^^^^^^^^^
  File "C:\Program Files\WindowsApps\PythonSoftwareFoundation.Python.3.11_3.11.2544.0_x64__qbz5n2kfra8p0\Lib\asyncio\windows_events.py", line 854, in _poll
    value = callback(transferred, key, ov)
            ^^^^^^^^^^^^^^^^^^^^^^^^^^^^^^
  File "C:\Program Files\WindowsApps\PythonSoftwareFoundation.Python.3.11_3.11.2544.0_x64__qbz5n2kfra8p0\Lib\asyncio\windows_events.py", line 498, in finish_recv
    raise ConnectionResetError(*exc.args)
ConnectionResetError: [WinError 64] 지정된 네트워크 이름을 더 이상 사용할 수 없습니다

The above exception was the direct cause of the following exception:

Traceback (most recent call last):
  File "C:\Users\dohwa\AppData\Local\Packages\PythonSoftwareFoundation.Python.3.11_qbz5n2kfra8p0\LocalCache\local-packages\Python311\site-packages\websockets\asyncio\server.py", line 376, in conn_handler
    await self.handler(connection)
  File "C:\Users\dohwa\Desktop\MyPlugin\printer_server_websocket\src\websocket\server.py", line 63, in handler
    async for message in websocket:
  File "C:\Users\dohwa\AppData\Local\Packages\PythonSoftwareFoundation.Python.3.11_qbz5n2kfra8p0\LocalCache\local-packages\Python311\site-packages\websockets\asyncio\connection.py", line 242, in __aiter__
    yield await self.recv()
          ^^^^^^^^^^^^^^^^^
  File "C:\Users\dohwa\AppData\Local\Packages\PythonSoftwareFoundation.Python.3.11_qbz5n2kfra8p0\LocalCache\local-packages\Python311\site-packages\websockets\asyncio\connection.py", line 322, in recv
    raise self.protocol.close_exc from self.recv_exc
websockets.exceptions.ConnectionClosedError: no close frame received or sent
2025-06-12 17:17:41,475 - INFO - 클라이언트 연결 해제. 현재 연결 수: 0
2025-06-12 17:17:41,475 - ERROR - connection handler failed
Traceback (most recent call last):
  File "C:\Users\dohwa\AppData\Local\Packages\PythonSoftwareFoundation.Python.3.11_qbz5n2kfra8p0\LocalCache\local-packages\Python311\site-packages\websockets\asyncio\server.py", line 376, in conn_handler
    await self.handler(connection)
  File "C:\Users\dohwa\Desktop\MyPlugin\printer_server_websocket\src\websocket\server.py", line 63, in handler
    async for message in websocket:
  File "C:\Users\dohwa\AppData\Local\Packages\PythonSoftwareFoundation.Python.3.11_qbz5n2kfra8p0\LocalCache\local-packages\Python311\site-packages\websockets\asyncio\connection.py", line 242, in __aiter__
    yield await self.recv()
          ^^^^^^^^^^^^^^^^^
  File "C:\Users\dohwa\AppData\Local\Packages\PythonSoftwareFoundation.Python.3.11_qbz5n2kfra8p0\LocalCache\local-packages\Python311\site-packages\websockets\asyncio\connection.py", line 322, in recv
    raise self.protocol.close_exc from self.recv_exc
websockets.exceptions.ConnectionClosedError: no close frame received or sent
2025-06-12 17:31:12,597 - INFO - connection open
2025-06-12 17:31:12,597 - INFO - 새로운 클라이언트 연결됨. 현재 연결 수: 1
2025-06-12 17:31:33,122 - INFO - connection open
2025-06-12 17:31:33,122 - INFO - 새로운 클라이언트 연결됨. 현재 연결 수: 2
2025-06-12 17:31:34,195 - INFO - 주문 수신: {'order_id': '27', 'customer_name': '미래새한감정평가법인', 'items': [{'name': '아토키토 포케', 'quantity': 1, 'price': 10900, 'options': ['소스 안먹어요 X']}], 'payment_method': '현장결제'}
2025-06-12 17:31:35,918 - INFO - 주문 수신: {'order_id': '27', 'customer_name': '미래새한감정평가법인', 'items': [{'name': '아토키토 포케', 'quantity': 1, 'price': 10900, 'options': ['소스 안먹어요 X']}], 'payment_method': '현장결제'}
2025-06-12 17:31:36,897 - INFO - 주문 수신: {'order_id': '27', 'customer_name': '미래새한감정평가법인', 'items': [{'name': '아토키토 포케', 'quantity': 1, 'price': 10900, 'options': ['소스 안먹어요 X']}], 'payment_method': '현장결제'}
2025-06-12 17:31:45,111 - INFO - 클라이언트 연결 해제. 현재 연결 수: 1
2025-06-12 17:31:45,111 - ERROR - connection handler failed
Traceback (most recent call last):
  File "C:\Program Files\WindowsApps\PythonSoftwareFoundation.Python.3.11_3.11.2544.0_x64__qbz5n2kfra8p0\Lib\asyncio\windows_events.py", line 494, in finish_recv
    return ov.getresult()
           ^^^^^^^^^^^^^^
OSError: [WinError 64] 지정된 네트워크 이름을 더 이상 사용할 수 없습니다

During handling of the above exception, another exception occurred:

Traceback (most recent call last):
  File "C:\Program Files\WindowsApps\PythonSoftwareFoundation.Python.3.11_3.11.2544.0_x64__qbz5n2kfra8p0\Lib\asyncio\proactor_events.py", line 286, in _loop_reading
    length = fut.result()
             ^^^^^^^^^^^^
  File "C:\Program Files\WindowsApps\PythonSoftwareFoundation.Python.3.11_3.11.2544.0_x64__qbz5n2kfra8p0\Lib\asyncio\windows_events.py", line 854, in _poll
    value = callback(transferred, key, ov)
            ^^^^^^^^^^^^^^^^^^^^^^^^^^^^^^
  File "C:\Program Files\WindowsApps\PythonSoftwareFoundation.Python.3.11_3.11.2544.0_x64__qbz5n2kfra8p0\Lib\asyncio\windows_events.py", line 498, in finish_recv
    raise ConnectionResetError(*exc.args)
ConnectionResetError: [WinError 64] 지정된 네트워크 이름을 더 이상 사용할 수 없습니다

The above exception was the direct cause of the following exception:

Traceback (most recent call last):
  File "C:\Users\dohwa\AppData\Local\Packages\PythonSoftwareFoundation.Python.3.11_qbz5n2kfra8p0\LocalCache\local-packages\Python311\site-packages\websockets\asyncio\server.py", line 376, in conn_handler
    await self.handler(connection)
  File "C:\Users\dohwa\Desktop\MyPlugin\printer_server_websocket\src\websocket\server.py", line 63, in handler
    async for message in websocket:
  File "C:\Users\dohwa\AppData\Local\Packages\PythonSoftwareFoundation.Python.3.11_qbz5n2kfra8p0\LocalCache\local-packages\Python311\site-packages\websockets\asyncio\connection.py", line 242, in __aiter__
    yield await self.recv()
          ^^^^^^^^^^^^^^^^^
  File "C:\Users\dohwa\AppData\Local\Packages\PythonSoftwareFoundation.Python.3.11_qbz5n2kfra8p0\LocalCache\local-packages\Python311\site-packages\websockets\asyncio\connection.py", line 322, in recv
    raise self.protocol.close_exc from self.recv_exc
websockets.exceptions.ConnectionClosedError: no close frame received or sent
2025-06-12 17:31:53,521 - INFO - 클라이언트 연결 해제. 현재 연결 수: 0
2025-06-12 17:31:53,521 - ERROR - connection handler failed
Traceback (most recent call last):
  File "C:\Users\dohwa\AppData\Local\Packages\PythonSoftwareFoundation.Python.3.11_qbz5n2kfra8p0\LocalCache\local-packages\Python311\site-packages\websockets\asyncio\server.py", line 376, in conn_handler
    await self.handler(connection)
  File "C:\Users\dohwa\Desktop\MyPlugin\printer_server_websocket\src\websocket\server.py", line 63, in handler
    async for message in websocket:
  File "C:\Users\dohwa\AppData\Local\Packages\PythonSoftwareFoundation.Python.3.11_qbz5n2kfra8p0\LocalCache\local-packages\Python311\site-packages\websockets\asyncio\connection.py", line 242, in __aiter__
    yield await self.recv()
          ^^^^^^^^^^^^^^^^^
  File "C:\Users\dohwa\AppData\Local\Packages\PythonSoftwareFoundation.Python.3.11_qbz5n2kfra8p0\LocalCache\local-packages\Python311\site-packages\websockets\asyncio\connection.py", line 322, in recv
    raise self.protocol.close_exc from self.recv_exc
websockets.exceptions.ConnectionClosedError: no close frame received or sent
